1. Tried to run comp.py 

Error encountered.

Traceback (most recent call last):
  File "C:\ProgramData\Anaconda3\lib\site-packages\pandas\core\indexes\base.py", line 2442, in get_loc
    return self._engine.get_loc(key)
  File "pandas\_libs\index.pyx", line 132, in pandas._libs.index.IndexEngine.get_loc
  File "pandas\_libs\index.pyx", line 154, in pandas._libs.index.IndexEngine.get_loc
  File "pandas\_libs\hashtable_class_helper.pxi", line 1210, in pandas._libs.hashtable.PyObjectHashTable.get_item
  File "pandas\_libs\hashtable_class_helper.pxi", line 1218, in pandas._libs.hashtable.PyObjectHashTable.get_item
KeyError: 'index'

During handling of the above exception, another exception occurred:

Traceback (most recent call last):
  File "comp.py", line 259, in <module>
    compare_scenarios(list(reversed(result_files)), comp_filename)
  File "comp.py", line 135, in compare_scenarios
    esum.set_index(['index', 'pro'], inplace=True)
  File "C:\ProgramData\Anaconda3\lib\site-packages\pandas\core\frame.py", line 2830, in set_index
    level = frame[col]._values
  File "C:\ProgramData\Anaconda3\lib\site-packages\pandas\core\frame.py", line 1964, in __getitem__
    return self._getitem_column(key)
  File "C:\ProgramData\Anaconda3\lib\site-packages\pandas\core\frame.py", line 1971, in _getitem_column
    return self._get_item_cache(key)
  File "C:\ProgramData\Anaconda3\lib\site-packages\pandas\core\generic.py", line 1645, in _get_item_cache
    values = self._data.get(item)
  File "C:\ProgramData\Anaconda3\lib\site-packages\pandas\core\internals.py", line 3590, in get
    loc = self.items.get_loc(item)
  File "C:\ProgramData\Anaconda3\lib\site-packages\pandas\core\indexes\base.py", line 2444, in get_loc
    return self._engine.get_loc(self._maybe_cast_indexer(key))
  File "pandas\_libs\index.pyx", line 132, in pandas._libs.index.IndexEngine.get_loc
  File "pandas\_libs\index.pyx", line 154, in pandas._libs.index.IndexEngine.get_loc
  File "pandas\_libs\hashtable_class_helper.pxi", line 1210, in pandas._libs.hashtable.PyObjectHashTable.get_item
  File "pandas\_libs\hashtable_class_helper.pxi", line 1218, in pandas._libs.hashtable.PyObjectHashTable.get_item
KeyError: 'index'

******************************************RESOLVED***********************************************************
--------------------------------------------------------------------------------------------------------------